### 在Java 7中重新抛出异常

在一个*catch*块中捕获一个异常时，有时希望重新抛出异常，那么此异常不仅可以被当前方法处理，还可以被调用当前方法的方法处理。

但是在Java 7以前只有基类异常才能被重新抛出。当有不止一个异常需要被抛出时，就不得不在方法的声明中声明抛出一个基类异常类型。现在在Java 1.7中，方法可以抛出的异常有了更多选择。

#### 准备

在Java中要重新抛出异常，必须首先捕获它们，然后在*catch*块中使用*throw*关键字重新抛出异常。Java 7中新的异常重新抛出技术要求：

* 在*catch*块里使用一个基类异常类型
* 从*catch*块中使用*throw*关键字抛出基类异常的衍生类异常
* 方法签名中抛出衍生类异常

#### 动手

1、修改*捕获多个异常来改进类型检查*一节中的*ReflectiveOperationExceptionExample*类。修改*main*方法，在*try*块中调用*deleteFile*方法，如下：

```java
    public static void main(String[] args) {
        try {
            deleteFile(Paths.get(new URI("file:///tmp.txt")));
        } catch (URISyntaxException e) {
            e.printStackTrace();
        } catch (IOException e) {
            e.printStackTrace();
        }
    }
```

2、*deleteFile*方法如下：

```java
    private static void deleteFile(Path path) throws NoSuchFileException, DirectoryNotEmptyException {
        try {
            Files.delete(path);
        } catch (IOException ex) {
            if (path.toFile().isDirectory()) {
                throw new DirectoryNotEmptyException(null);
            } else {
                throw new NoSuchFileException(null);
            }
        }
    }
```

3、指定一个不存在的文件路径执行程序，输出应该如下：

    java.nio.fle.NoSuchFileException
       at packt.RefectiveOperationExceptionExample.deleteFile(RefectiveOperationExceptionExample.java:33)
       at packt.RefectiveOperationExceptionExample.main(RefectiveOperationExceptionExample.java:16)

#### 原理

*main*方法调用*deleteFile*方法并处理它的异常。*deleteFile*声明自己可能抛出*NoSuchFileException*和*DirectoryNotEmptyException*异常。基类*IOException*在*catch*块中使用。*catch*块中使用*File*的*isDirectory*来判断到底抛出那个异常，一旦判断条件成立就抛出对应的异常。*Files*类的将在*第四章 管理文件和目录*一章中详细讨论。

通过精确地指定方法可能抛出的异常，就可以更清楚地告诉调用者方法的行为。并且，这也防止了在方法里可能不慎抛出其他的*IOException*的衍生类。这个例子的缺点是，如果其他的异常，比如*FileSystemException*，是根异常，那么可能丢失这个异常的信息，它会被*deleteFile*方法捕获，因为它是*IOException*的衍生类。但是将不会在方法中处理它，也不会把它向外传递给调用方法。

#### 其他

前面的三节基本覆盖了Java 7中的异常处理。

----------
#### 译注

前面*deleteFile*方法并没有说明白Java 7中重新抛出异常的含义。看看Oracle官网的说明[catch-multiple](http://docs.oracle.com/javase/7/docs/technotes/guides/language/catch-multiple.html):

**以更Inclusive的类型检测重新抛出异常**

JavaSE 7编译器将执行比以前更为精确的异常重新抛出分析，这使得可以在方法声明的*throws*中指定更为精确的异常类型。

考虑如下的例子：

```java
    static class FirstException extends Exception {    }

    static class SecondException extends Exception {    }

    public void rethrowException(String exceptionName) throws FirstException, SecondException {
        try {
            if (exceptionName.equals("First")) {
                throw new FirstException();
            } else {
                throw new SecondException();
            }
        } catch (Exception e) {
            throw e;
        }
    }
```

例子中*try*块要么抛出*FirstException*，要么抛出*SecondException*。假设想在方法*rethrowException*的*throws*中指定抛出这两个异常类型，在Java SE 7之前，不可以这么做。因为*catch*语句的参数*e*的类型是*Exception*，在*catch*块中抛出*e*，那么就必须在方法*rethrowException*的*throws*中指定异常*Exceptio*.

而在 Java SE 7中，就可以在方法*rethrowException*声明的*throws*语句中指定*FirstException*和*SecondException*。编译器会确定*throw e*抛出的异常一定是来自*try*块的，并且只能是*try*块中抛出的*FirstException*和*SecondException*。虽然*catch*的是*e*的类型是*Exception*，编译器会确定它是*FirstException*或*SecondException*其中一个的实例。

```java
    public void rethrowException(String exceptionName) throws FirstException, SecondException {
        try {
            // ...
        } catch (Exception e) {
            throw e;
        }
    }
```

如果在*catch*中*catch*的参数被赋予了另一个值，这个特性会被禁止。如果这样，就必须在方法声明的*throws*语句中指定*Exception*异常类型。

更进一步，在Java SE 7中，如果在*catch*子句中声明了一个或多个异常类型，并且在这个*catch*块重新抛出它们，编译器会校验重新抛出类型是否满足如下条件：

* *try*块有能力抛出这个异常
* 没有其他的前导*catch*块处理这个异常
* 它是*catch*子句异常参数的一个子类或超类。

Java SE 7编译器允许在*rethrowException*方法声明的*throws*子句中指定异常类型*FirstException*和*SecondException*，并且可以重新抛出任一个在*throws*中声明的异常类型的超类。

在Java SE 7以前，不可以重新抛出*catch*子句异常参数的超类型。编译器会在*throw e*处报错：*unreported exception Exception; must be caught or declared to be thrown*，它会检查重新抛出的异常是否是方法*rethrowException*方法声明的*throws*子句中声明的异常类型的导出类。但是*catch*的异常参数*e*的类型是*Exception*，它是*FirstException*和*SecondException*的超类，而不是它们的子类。