### 捕获多个异常类型以改进类型检测

在一个*try*块中可能会抛出多个异常，于是一系列对应的*catch*块被用来捕获和处理这些异常。经常处理这些异常的动作是一样的，比如在用日志记录异常的时候。

在Java 7中，可以在一个单独的*catch*块中处理多个异常。而在以前，通常解决这个问题的可选方法是捕获更高级别的异常类型来处理*try*块中抛出的多个异常。现在在Java 7中就没必要再这么干了。

#### 准备

通过如下步骤在一个单独的*catch*块中捕获多个异常：

* 添加一个*catch*块
* 在*catch*后的括号中包含多个由*|*分割的异常

#### 动手

这个例子会处理来自用户的非法输入，并在日中中记录它们。这个简单的例子足以说明如何处理多个异常.

1、新建两个类：*MultipleExceptions*和*InvalidParameter*。*InvalidParameter*类用来处理用户的非法输入。*MultipleExceptions*类里包含*main*方法和例子代码：

2、新建*InvalidParameter*如下：

```java
public class InvalidParameter extends Exception {
    public InvalidParameter() {
        super("Invalid Parameter");
    }
}
```

3、下一步，使用*java.util.logging.Logger*创建*MultipleExceptions*类：

```java
public class MultipleExceptions {

    private static final Logger logger = Logger.getLogger(MultipleExceptions.class.getName());

    public static void main(String[] args) {
        System.out.print("Enter a number:");

        try {
            Scanner scanner = new Scanner(System.in);
            int number = scanner.nextInt();
            if (number < 0) {
                throw new InvalidParameter();
            }
            System.out.println("The number is: " + number);
        } catch (InputMismatchException | InvalidParameter e) {
            logger.log(Level.INFO, "Invalid input, try again");
        }
    }
}
```

4、运行程序，键入不同的输入。键入合法数字，比如**12**，结果输出如下：

    Enter a number:12
    The number is: 12

5、键入非数字的非法输入，比如**cat**，或这个一个负数，例如***-5*，结果输出如下：

    Enter a number: cat
    Invalid input, try again
    Aug 28, 2011 1:48:59 PM packt.MultipleExceptions main
    INFO: Invalid input, try again

    Enter a number: -5
    Invalid input, try again
    Aug 28, 2011 1:49:20 PM packt
    INFO: Invalid input, try again

#### 原理

当有错误时*logger*会在日志文件中记录信息，测试中的输出由NetBeans输出并显示。

发生异常后就会进入*catch*块。异常* java.util.InputMismatchException*和*InvalidParameter*出现在一个*catch*语句中，并通过竖线分割。另外只有一个单独的变量*e*用于表示这两个异常。

在需要处理几个异常，并且处理方式是一样的时候，这种处理方式就很用。当一个*catch*块处理多个异常时，*catch*块的参数隐式的是*final*的，这意味着不可以给它赋一个新值。下面的代码是非法的，会导致一个语法错误：

```java
        } catch (InputMismatchException | InvalidParameter e) {
            e = new Exception(); //The parameter e of a multi-catch block cannot be assigned
            logger.log(Level.INFO, "Invalid input, try again");
        }
```

使用*multiple catch blocks*除了可以使代码更具有阅读性和简洁以外，编译后的字节码也会更小，并且还不会产出重复代码。

#### 其他

使用一个*catch*块捕获多个异常，当这些异常类型中存在基类或一组异常类型时会有影响。另外，使用断言也有助于创建健壮的应用。这些点如下：

* 异常基类和*java.lang.ReflectiveOperationException*的使用
* 在 Java 7中使用断言

**异常基类和*java.lang.ReflectiveOperationException*的使用**

当不同的异常类型需要按照同样的方法处理时，在一个*catch*块中捕获多个异常就很有用。但是如果这些异常继承自同一个异常基类，那么选择直接捕获异常基类会更简单。一个例子从*IOException*衍生的那些异常类型。

比如，*Files*类的*delete*方法可能会抛出如下四个异常:

    java.nio.file.NoSuchFileException
    java.nio.file.DirectoryNotEmptyException
    java.io.IOException
    java.lang.SecurityException

显而易见，*NoSuchFileException*和*DirectoryNotEmptyException*都最终继承自*IOException*，因此在如下的例子中捕获*IOException*就足够了：

```java
    public static void main(String[] args) {
        try {
            // deleteFile(Paths.get(new URI("file:///tmp.txt")));
            Files.delete(Paths.get(new URI("file:///tmp.txt")));
        } catch (URISyntaxException e) {
            e.printStackTrace();
        } catch (IOException e) {
            e.printStackTrace();
        }
    }
```

*URISyntaxException*异常可能在*URI*的构造方法中抛出，在*第四章 管理文件和目录*的*删除文件和目录*一节，会讨论的*delete*方法的细节。

在Java 7中，*java.lang*包中新加了一个异常类型*java.lang.ReflectiveOperationException*，它是如下异常类的基类：
    ClassNotFoundException
    IllegalAccessException
    InstantiationException
    InvocationTargetException
    NoSuchFieldException
    NoSuchMethodException

这个异常类简化了反射相关异常类的处理。多异常捕获机制更适合那些没有公共基类异常类型的处理。

    一般而言，需要尽可能的捕获直接引起问题的异常。比如在处理文件不存在时，相比于更范围更广的*Exception*，捕获*NoSuchFileException*更好，它提供了更多的异常信息。

**在 Java 7中使用断言**

使用断言有助于构建更健壮的应用。可以在[assert](http://download.oracle.com/javase/1.4.2/docs/guide/lang/assert.html)找到关于断言的更多介绍。Java 7新家了一个构造方法，允许在用户产生的断言错误中附加一个消息。这个构造方法有两个参数，第一个是和*AssertionError*关联的消息，第二个是一个*Throwable*.

在本节前面的*MultipleExceptions*类中，会测试看输入的数字是否小于零，如果是会抛出一个异常。如果输入的数字大于10，下面会通过抛出一个*AssertionError*来演示新的构造方法的使用。

添加如下代码在*main*方法的*if*语句后：

```java
            if (number > 10) {
                throw new AssertionError("Number was too big", new Throwable("Throwable assertion message"));
            }
```

执行程序，再次输入12，会得到下面的类似输出:
    Enter a number: 12
    Exception in thread "main" java.lang.AssertionError: Number was too big
    at packt.MultipleExceptions.main(MultipleExceptions.java:28)
    Caused by: java.lang.Throwable: Throwable assertion message
    ... 1 more
    Java Result: 1

在Java 7之前，用户产生的*AssertionError*是不可以关联一个消息的。

#### 更多

*Files*的使用在*第四章 管理文件和目录*中会详细讨论。